<?xml version="1.0" encoding="UTF-8"?>
<testsuite name="test_calculate_balance_tests.TestCalculateBalance-20250424145125" tests="7" file="test_calculate_balance_tests.py" time="0.010" timestamp="2025-04-24T14:51:25" failures="1" errors="0" skipped="0">
	<testcase classname="test_calculate_balance_tests.TestCalculateBalance" name="test_balance_file_not_json" time="0.001" timestamp="2025-04-24T14:51:25"/>
	<testcase classname="test_calculate_balance_tests.TestCalculateBalance" name="test_calculate_balance_1" time="0.004" timestamp="2025-04-24T14:51:25"/>
	<testcase classname="test_calculate_balance_tests.TestCalculateBalance" name="test_file_iban_not_found" time="0.001" timestamp="2025-04-24T14:51:25"/>
	<testcase classname="test_calculate_balance_tests.TestCalculateBalance" name="test_file_not_json" time="0.001" timestamp="2025-04-24T14:51:25"/>
	<testcase classname="test_calculate_balance_tests.TestCalculateBalance" name="test_file_skip_loop" time="0.001" timestamp="2025-04-24T14:51:25"/>
	<testcase classname="test_calculate_balance_tests.TestCalculateBalance" name="test_file_wrong_iban_number" time="0.000" timestamp="2025-04-24T14:51:25"/>
	<testcase classname="test_calculate_balance_tests.TestCalculateBalance" name="test_file_not_found" time="0.003" timestamp="2025-04-24T14:51:25">
		<failure type="AssertionError" message="True != False : IBAN not found"><![CDATA[Traceback (most recent call last):
  File "/Library/Frameworks/Python.framework/Versions/3.9/lib/python3.9/unittest/case.py", line 59, in testPartExecutor
    yield
  File "/Library/Frameworks/Python.framework/Versions/3.9/lib/python3.9/unittest/case.py", line 592, in run
    self._callTestMethod(testMethod)
  File "/Library/Frameworks/Python.framework/Versions/3.9/lib/python3.9/unittest/case.py", line 550, in _callTestMethod
    method()
  File "/Users/mimi/PycharmProjects/G88.2025.T03.GE3/src/unittest/python/test_calculate_balance_tests.py", line 100, in test_file_not_found
    self.assertEqual(True,res,msg)
  File "/Library/Frameworks/Python.framework/Versions/3.9/lib/python3.9/unittest/case.py", line 837, in assertEqual
    assertion_func(first, second, msg=msg)
  File "/Library/Frameworks/Python.framework/Versions/3.9/lib/python3.9/unittest/case.py", line 830, in _baseAssertEqual
    raise self.failureException(msg)
AssertionError: True != False : IBAN not found
]]></failure>
	</testcase>
</testsuite>
