<?xml version="1.0" encoding="UTF-8"?>
<testsuite name="unittest.loader._FailedTest-20250423165746" tests="3" file="unittest/loader.py" time="0.004" timestamp="2025-04-23T16:57:46" failures="0" errors="3" skipped="0">
	<testcase classname="unittest.loader._FailedTest" name="test_deposit_tests" time="0.002" timestamp="2025-04-23T16:57:46">
		<error type="ImportError" message="Failed to import test module: test_deposit_tests
Traceback (most recent call last):
  File &quot;/opt/anaconda3/lib/python3.12/unittest/loader.py&quot;, line 137, in loadTestsFromName
    module = __import__(module_name)
             ^^^^^^^^^^^^^^^^^^^^^^^
  File &quot;/Users/anncasey/PycharmProjects/G88.2025.T03.GE3-/src/unittest/python/test_deposit_tests.py&quot;, line 8, in &lt;module&gt;
    from freezegun import freeze_time
ModuleNotFoundError: No module named 'freezegun'
"><![CDATA[Traceback (most recent call last):
  File "/opt/anaconda3/lib/python3.12/unittest/case.py", line 58, in testPartExecutor
    yield
  File "/opt/anaconda3/lib/python3.12/unittest/case.py", line 634, in run
    self._callTestMethod(testMethod)
    ^^^^^^^^^^^^^^^^^
  File "/opt/anaconda3/lib/python3.12/unittest/case.py", line 589, in _callTestMethod
    if method() is not None:
    ^^^^^^^^^^^^^^^^^
  File "/opt/anaconda3/lib/python3.12/unittest/loader.py", line 33, in testFailure
    raise self._exception
    ^^^^^^^^^^^^^^^^^
ImportError: Failed to import test module: test_deposit_tests
Traceback (most recent call last):
  File "/opt/anaconda3/lib/python3.12/unittest/loader.py", line 137, in loadTestsFromName
    module = __import__(module_name)
             ^^^^^^^^^^^^^^^^^^^^^^^
  File "/Users/anncasey/PycharmProjects/G88.2025.T03.GE3-/src/unittest/python/test_deposit_tests.py", line 8, in <module>
    from freezegun import freeze_time
ModuleNotFoundError: No module named 'freezegun'

]]></error>
	</testcase>
	<testcase classname="unittest.loader._FailedTest" name="test_transfer_request_tests" time="0.001" timestamp="2025-04-23T16:57:46">
		<error type="ImportError" message="Failed to import test module: test_transfer_request_tests
Traceback (most recent call last):
  File &quot;/opt/anaconda3/lib/python3.12/unittest/loader.py&quot;, line 137, in loadTestsFromName
    module = __import__(module_name)
             ^^^^^^^^^^^^^^^^^^^^^^^
  File &quot;/Users/anncasey/PycharmProjects/G88.2025.T03.GE3-/src/unittest/python/test_transfer_request_tests.py&quot;, line 8, in &lt;module&gt;
    from freezegun import freeze_time
ModuleNotFoundError: No module named 'freezegun'
"><![CDATA[Traceback (most recent call last):
  File "/opt/anaconda3/lib/python3.12/unittest/case.py", line 58, in testPartExecutor
    yield
  File "/opt/anaconda3/lib/python3.12/unittest/case.py", line 634, in run
    self._callTestMethod(testMethod)
    ^^^^^^^^^^^^^^^^^
  File "/opt/anaconda3/lib/python3.12/unittest/case.py", line 589, in _callTestMethod
    if method() is not None:
    ^^^^^^^^^^^^^^^^^
  File "/opt/anaconda3/lib/python3.12/unittest/loader.py", line 33, in testFailure
    raise self._exception
    ^^^^^^^^^^^^^^^^^
ImportError: Failed to import test module: test_transfer_request_tests
Traceback (most recent call last):
  File "/opt/anaconda3/lib/python3.12/unittest/loader.py", line 137, in loadTestsFromName
    module = __import__(module_name)
             ^^^^^^^^^^^^^^^^^^^^^^^
  File "/Users/anncasey/PycharmProjects/G88.2025.T03.GE3-/src/unittest/python/test_transfer_request_tests.py", line 8, in <module>
    from freezegun import freeze_time
ModuleNotFoundError: No module named 'freezegun'

]]></error>
	</testcase>
	<testcase classname="unittest.loader._FailedTest" name="test_calculate_balance_tests" time="0.001" timestamp="2025-04-23T16:57:46">
		<error type="ImportError" message="Failed to import test module: test_calculate_balance_tests
Traceback (most recent call last):
  File &quot;/opt/anaconda3/lib/python3.12/unittest/loader.py&quot;, line 137, in loadTestsFromName
    module = __import__(module_name)
             ^^^^^^^^^^^^^^^^^^^^^^^
  File &quot;/Users/anncasey/PycharmProjects/G88.2025.T03.GE3-/src/unittest/python/test_calculate_balance_tests.py&quot;, line 9, in &lt;module&gt;
    from freezegun import freeze_time
ModuleNotFoundError: No module named 'freezegun'
"><![CDATA[Traceback (most recent call last):
  File "/opt/anaconda3/lib/python3.12/unittest/case.py", line 58, in testPartExecutor
    yield
  File "/opt/anaconda3/lib/python3.12/unittest/case.py", line 634, in run
    self._callTestMethod(testMethod)
    ^^^^^^^^^^^^^^^^^
  File "/opt/anaconda3/lib/python3.12/unittest/case.py", line 589, in _callTestMethod
    if method() is not None:
    ^^^^^^^^^^^^^^^^^
  File "/opt/anaconda3/lib/python3.12/unittest/loader.py", line 33, in testFailure
    raise self._exception
    ^^^^^^^^^^^^^^^^^
ImportError: Failed to import test module: test_calculate_balance_tests
Traceback (most recent call last):
  File "/opt/anaconda3/lib/python3.12/unittest/loader.py", line 137, in loadTestsFromName
    module = __import__(module_name)
             ^^^^^^^^^^^^^^^^^^^^^^^
  File "/Users/anncasey/PycharmProjects/G88.2025.T03.GE3-/src/unittest/python/test_calculate_balance_tests.py", line 9, in <module>
    from freezegun import freeze_time
ModuleNotFoundError: No module named 'freezegun'

]]></error>
	</testcase>
</testsuite>
